Workbook

Sheet Criteri
A1: Criteri di valutazione delle nicchie
A2: I pesi (in blu) sono una proposta: cambiali e i punteggi della Lista lunga si ricalcolano. Ogni nicchia riceve da 1 a 5 su ogni criterio.
A4: Criterio | B4: Domanda | C4: Peso | D4: Come si valuta (1 = peggio, 5 = meglio)
A5: Bisogno urgente / obbligo | B5: C'è una scadenza di legge o un costo evidente che spinge ad agire ora? | C5: 20 | D5: 1 = nice-to-have; 5 = obbligo di legge o costo alto e documentato
A6: Budget del cliente | B6: I clienti tipo hanno ricavi >1 M€ e capacità di spesa? | C6: 20 | D6: 1 = micro-imprese; 5 = PMI con >1 M€ di ricavi e abitudine a pagare software
A7: Ricavi ricorrenti | B7: Il cliente paga ogni anno o ogni mese? | C7: 10 | D7: 1 = una tantum; 5 = abbonamento naturale
A8: Scalabilità | B8: Quanto costa servire un cliente in più? Margine? | C8: 15 | D8: 1 = molto lavoro per cliente; 5 = costo marginale quasi zero
A9: Canale di vendita | B9: Sai dove trovare i clienti e come raggiungerli? | C9: 10 | D9: 1 = nessun canale chiaro; 5 = canale noto (associazioni, rivenditori, consulenti)
A10: Concorrenza (5 = poca) | B10: Quanti concorrenti e quanto forti? | C10: 10 | D10: 1 = mercato saturo; 5 = pochi o nessuno ben posizionato
A11: Vantaggio tuo | B11: Capisci il problema meglio di chi lo risolve oggi? | C11: 10 | D11: 1 = nessun vantaggio; 5 = lo conosci dall'interno
A12: Testabile a poco prezzo | B12: Puoi verificare la domanda con un prototipo e conversazioni, senza spendere? | C12: 5 | D12: 1 = serve capitale; 5 = test in 2 settimane a costo zero
B13: Somma dei pesi | C13: =SUM(C5:C12)

Sheet Lista lunga
A1: Lista lunga delle nicchie
A2: Una riga per nicchia (lista lunga, Fase 1). Il segnale è solo il punto di partenza: la colonna Note dice se è stato verificato in ricerca (stampa di settore, non fonti ufficiali) o se è solo un'ipotesi. In blu le celle da compilare nelle fasi 2-3: stima di aziende target e di prezzo (con fonte) e punteggi 1-5. 'Clienti per 1 M€' e 'Punteggio' si calcolano da soli.
J4: Peso → | K4: =Criteri!C5 | L4: =Criteri!C6 | M4: =Criteri!C7 | N4: =Criteri!C8 | O4: =Criteri!C9 | P4: =Criteri!C10 | Q4: =Criteri!C11 | R4: =Criteri!C12
A5: N | B5: Nicchia | C5: Cliente tipo | D5: Tipo di segnale | E5: Fonte del segnale | F5: Aziende target (stima) | G5: Fonte della stima | H5: Prezzo annuo per cliente (€) | I5: Clienti per 1 M€ di ricavi | J5: Concorrenti noti | K5: Bisogno urgente / obbligo | L5: Budget del cliente | M5: Ricavi ricorrenti | N5: Scalabilità | O5: Canale di vendita | P5: Concorrenza (5 = poca) | Q5: Vantaggio tuo | R5: Testabile a poco prezzo | S5: Punteggio ponderato (1-5) | T5: Stato | U5: Note
A6: 1 | B6: NIS2: preparazione alla conformità per PMI fornitrici di soggetti critici | C6: PMI in filiere critiche; consulenti e MSP come canale | D6: Obbligo di legge | E6: Noze; Agenda Digitale | F6: 20000 | G6: Stampa di settore: 20.000–50.000 enti potenzialmente coinvolti (non registrati) (affidabilità: Media) | H6: 1500 | I6: =IF(H6>0,ROUND(1000000/H6,0),"") | S6: =IF(COUNT(K6:R6)=0,"",ROUND(SUMPRODUCT(K6:R6,K$4:R$4)/SUM(K$4:R$4),2)) | T6: Da studiare | U6: Segnale verificato in ricerca (stampa di settore). Notifica incidenti operativa dal 15/01/2026; misure di base con scadenze da ottobre 2026 per chi ha ricevuto la comunicazione ad aprile 2025. Mercato affollato di consulenti. Numero di imprese coinvolte non trovato.
A7: 2 | B7: NIS2 per MSP e consulenti: piattaforma multi-cliente per gestire la conformità di più aziende | C7: MSP, studi di consulenza IT | D7: Obbligo di legge | E7: Noze; Agenda Digitale | F7: 5000 | G7: Mia ipotesi: numero di MSP e studi di consulenza IT rilevanti (nessun dato trovato) (affidabilità: Bassa) | H7: 2400 | I7: =IF(H7>0,ROUND(1000000/H7,0),"") | S7: =IF(COUNT(K7:R7)=0,"",ROUND(SUMPRODUCT(K7:R7,K$4:R$4)/SUM(K$4:R$4),2)) | T7: Da studiare | U7: Segnale verificato in ricerca (stampa di settore). Variante della precedente: vendi al canale, non alla PMI finale. Da confrontare con piattaforme esistenti.
A8: 3 | B8: Cyber Resilience Act: gestione segnalazione vulnerabilità e fascicolo tecnico per produttori | C8: Produttori di prodotti con elementi digitali (elettronica, IoT, macchine con software) | D8: Obbligo di legge | E8: Agenda Digitale; IPSOA | F8: 3000 | G8: ANIE: ~1.100 aziende associate (altre fonti: 1.600); più costruttori con software. Perimetro CRA non trovato (affidabilità: Bassa) | H8: 3000 | I8: =IF(H8>0,ROUND(1000000/H8,0),"") | S8: =IF(COUNT(K8:R8)=0,"",ROUND(SUMPRODUCT(K8:R8,K$4:R$4)/SUM(K$4:R$4),2)) | T8: Da studiare | U8: Segnale verificato in ricerca (stampa di settore). Obbligo di segnalazione dall'11/09/2026 (preallarme in 24 ore); piena applicazione 11/12/2027; sanzioni fino a 15 M€ (stampa). Vantaggio tuo: medio-alto.
A9: 4 | B9: Direttiva RED (cybersicurezza): assistente alla conformità EN 18031 per produttori di apparecchi radio/IoT | C9: Produttori e importatori di apparecchi radio e dispositivi connessi | D9: Obbligo di legge | E9: TÜV SÜD; Yarix | F9: 800 | G9: Mia ipotesi: produttori e importatori di apparecchi radio in Italia (nessun dato trovato) (affidabilità: Bassa) | H9: 4000 | I9: =IF(H9>0,ROUND(1000000/H9,0),"") | S9: =IF(COUNT(K9:R9)=0,"",ROUND(SUMPRODUCT(K9:R9,K$4:R$4)/SUM(K$4:R$4),2)) | T9: Da studiare | U9: Segnale verificato in ricerca (stampa di settore). Applicabile dal 01/08/2025. Stato di armonizzazione degli standard discordante tra le fonti. Vantaggio tuo: alto (RF).
A10: 5 | B10: Regolamento Macchine 2023/1230: generatore di fascicolo tecnico e dichiarazione UE | C10: Costruttori di macchine (Lombardia è un polo) | D10: Obbligo di legge | E10: Certifico; UCIMU | F10: 5000 | G10: Federmacchine 2020: 5.050 imprese (dato vecchio) (affidabilità: Media-bassa) | H10: 2500 | I10: =IF(H10>0,ROUND(1000000/H10,0),"") | S10: =IF(COUNT(K10:R10)=0,"",ROUND(SUMPRODUCT(K10:R10,K$4:R$4)/SUM(K$4:R$4),2)) | T10: Da studiare | U10: Segnale verificato in ricerca (stampa di settore). Applicazione dal 20/01/2027; UCIMU chiede una proroga condizionata. Dettagli sulla documentazione tecnica non verificati.
A11: 6 | B11: AI Act: inventario dei sistemi di IA e conformità agli obblighi di trasparenza (art. 50) | C11: PMI che usano o forniscono sistemi di IA | D11: Obbligo di legge | E11: Agenda Digitale; Noze | I11: =IF(H11>0,ROUND(1000000/H11,0),"") | S11: =IF(COUNT(K11:R11)=0,"",ROUND(SUMPRODUCT(K11:R11,K$4:R$4)/SUM(K$4:R$4),2)) | T11: Da studiare | U11: Segnale verificato in ricerca (stampa di settore). Trasparenza dal 02/08/2026; alto rischio rinviato a dicembre 2027 / agosto 2028 (accordo provvisorio del 07/05/2026, da verificare in Gazzetta UE). Domanda specifica debole.
A12: 7 | B12: Trasparenza retributiva: annunci e report sul divario di genere | C12: Aziende con 100+ dipendenti, uffici HR | D12: Obbligo di legge | E12: QuiFinanza; PartitaIVA.it | I12: =IF(H12>0,ROUND(1000000/H12,0),"") | S12: =IF(COUNT(K12:R12)=0,"",ROUND(SUMPRODUCT(K12:R12,K$4:R$4)/SUM(K$4:R$4),2)) | T12: Da studiare | U12: Segnale verificato in ricerca (stampa di settore). Stato del decreto di recepimento discordante tra le fonti (D.Lgs. 96/2026?). Report annuale dal 07/06/2027 per 250+ dipendenti. Il target è piccolo: poche aziende con 100+ dipendenti.
A13: 8 | B13: PPWR imballaggi: gestione dati e dichiarazioni di conformità | C13: Produttori e utilizzatori di imballaggi (Lombardia ha molti) | D13: Obbligo di legge | E13: Assolombarda | I13: =IF(H13>0,ROUND(1000000/H13,0),"") | S13: =IF(COUNT(K13:R13)=0,"",ROUND(SUMPRODUCT(K13:R13,K$4:R$4)/SUM(K$4:R$4),2)) | T13: Da studiare | U13: Segnale verificato in ricerca (stampa di settore). Applicabile dal 12/08/2026; date di etichettatura discordanti (2026, 2027, 2028). Assolombarda ha attivato un desk dedicato.
A14: 9 | B14: Passaporto digitale di prodotto: raccolta dati per batterie e tessile | C14: Produttori di batterie e tessile | D14: Obbligo di legge | E14: Bluestone PIM; PMI.it | I14: =IF(H14>0,ROUND(1000000/H14,0),"") | S14: =IF(COUNT(K14:R14)=0,"",ROUND(SUMPRODUCT(K14:R14,K$4:R$4)/SUM(K$4:R$4),2)) | T14: Da studiare | U14: Segnale verificato in ricerca (stampa di settore). Batterie dal 18/02/2027; tessile non ancora definito. Dominato da grandi fornitori e dagli atti delegati.
A15: 10 | B15: Accessibilità digitale (EAA): audit e correzione per e-commerce | C15: E-commerce italiani | D15: Obbligo di legge | E15: Agenda Digitale; Iubenda | I15: =IF(H15>0,ROUND(1000000/H15,0),"") | S15: =IF(COUNT(K15:R15)=0,"",ROUND(SUMPRODUCT(K15:R15,K$4:R$4)/SUM(K$4:R$4),2)) | T15: Da studiare | U15: Segnale verificato in ricerca (stampa di settore). Obbligo dal 28/06/2025; piattaforma di segnalazione AgID dal 11/03/2026; sanzioni da verificare (nessun procedimento pubblico trovato a giugno 2026). Molti fornitori.
A16: 11 | B16: Iperammortamento 2026: pratica per perizia asseverata, certificazione e comunicazioni al GSE | C16: Studi di ingegneria che firmano perizie; imprese manifatturiere | D16: Incentivi / fondi | E16: Agenda Digitale; Pasquale Pillitteri | F16: 12000 | G16: CNI 2020: 4,5%–9% degli ingegneri ha firmato perizie, in media 10 ciascuno (+ ordine di grandezza mio) (affidabilità: Bassa) | H16: 600 | I16: =IF(H16>0,ROUND(1000000/H16,0),"") | S16: =IF(COUNT(K16:R16)=0,"",ROUND(SUMPRODUCT(K16:R16,K$4:R$4)/SUM(K$4:R$4),2)) | T16: Da studiare | U16: Segnale verificato in ricerca (stampa di settore). Piattaforma GSE dal 12/06/2026; comunicazione di completamento entro 15/11/2028. La perizia è di un ingegnere iscritto all'albo: collegato agli studi che stai contattando. Regole (soglie, SaaS) discordanti tra le fonti.
A17: 12 | B17: Fibra ottica: report di collaudo e documentazione per imprese di posa | C17: Imprese di posa fibra e installatori | D17: Incentivi / fondi | E17: Domani | F17: 1000 | G17: Mia ipotesi: nessun dato trovato sul numero di imprese di posa (affidabilità: Bassa) | H17: 2000 | I17: =IF(H17>0,ROUND(1000000/H17,0),"") | S17: =IF(COUNT(K17:R17)=0,"",ROUND(SUMPRODUCT(K17:R17,K$4:R$4)/SUM(K$4:R$4),2)) | T17: Da studiare | U17: Segnale verificato in ricerca (stampa di settore). Piano Italia 1 Giga in ritardo: 250–700 mila civici potrebbero uscire dal Piano. Committenti con portali propri; strumenti degli OTDR con report già inclusi.
A18: 13 | B18: Comunità energetiche: piattaforma di gestione per CER, condomini e comuni | C18: Promotori di CER, amministratori di condominio, comuni | D18: Incentivi / fondi | E18: InfoBuild Energia | I18: =IF(H18>0,ROUND(1000000/H18,0),"") | S18: =IF(COUNT(K18:R18)=0,"",ROUND(SUMPRODUCT(K18:R18,K$4:R$4)/SUM(K$4:R$4),2)) | T18: Da studiare | U18: Segnale verificato in ricerca (stampa di settore). Obiettivo di 15.000 CER a giugno 2026 probabilmente mancato; regole ancora instabili.
A19: 14 | B19: Diagnosi energetica obbligatoria: strumento per redigere e gestire le diagnosi | C19: Studi di ingegneria, ESCO, grandi imprese ed energivori | D19: Incentivi / fondi | E19: da cercare | I19: =IF(H19>0,ROUND(1000000/H19,0),"") | S19: =IF(COUNT(K19:R19)=0,"",ROUND(SUMPRODUCT(K19:R19,K$4:R$4)/SUM(K$4:R$4),2)) | T19: Da studiare | U19: Segnale da verificare: non cercato. Obbligo ricorrente (ogni 4 anni per le imprese soggette). Da verificare sulle norme e sul mercato.
A20: 15 | B20: FWA: pianificazione e monitoraggio per piccoli operatori wireless | C20: Piccoli provider FWA/WISP | D20: Altro | E20: Segugio (dati AGCOM) | F20: 400 | G20: Consulente 2022: 'centinaia' di WISP in Italia (affidabilità: Bassa) | H20: 1500 | I20: =IF(H20>0,ROUND(1000000/H20,0),"") | S20: =IF(COUNT(K20:R20)=0,"",ROUND(SUMPRODUCT(K20:R20,K$4:R$4)/SUM(K$4:R$4),2)) | T20: Da studiare | U20: Segnale verificato in ricerca (stampa di settore). Oltre 2,7 milioni di linee FWA, +13% in un anno; frequenze 26 GHz in assegnazione. Nessun dato recente sul numero di piccoli provider.
A21: 16 | B21: Audit e ottimizzazione dei costi telecom per PMI | C21: PMI con molte linee e contratti | D21: Altro | E21: da cercare | I21: =IF(H21>0,ROUND(1000000/H21,0),"") | S21: =IF(COUNT(K21:R21)=0,"",ROUND(SUMPRODUCT(K21:R21,K$4:R$4)/SUM(K$4:R$4),2)) | T21: Da studiare | U21: Solo ipotesi nostra: domanda non verificata. Vantaggio tuo alto; modello a risparmio condiviso. Da verificare quanto si risparmia davvero.
A22: 17 | B22: Pianificazione turni e presenze per magazzini, logistica e conto terzi | C22: Logistica, confezionamento conto terzi, magazzini | D22: Acquisizioni di verticali | E22: Aventis Advisors (Zucchetti) | I22: =IF(H22>0,ROUND(1000000/H22,0),"") | S22: =IF(COUNT(K22:R22)=0,"",ROUND(SUMPRODUCT(K22:R22,K$4:R$4)/SUM(K$4:R$4),2)) | T22: Da studiare | U22: Zucchetti ha acquisito la maggioranza di AWMS (personale per fabbriche e logistica): segnale che il verticale vale. In zona: 6 imprese di conto terzi nell'elenco. Software di turni già presenti.
A23: 18 | B23: Gestione commesse e avanzamento lavori per piccole imprese edili e impiantisti | C23: Imprese edili, impiantisti | D23: Acquisizioni di verticali | E23: Aventis Advisors (TeamSystem) | I23: =IF(H23>0,ROUND(1000000/H23,0),"") | S23: =IF(COUNT(K23:R23)=0,"",ROUND(SUMPRODUCT(K23:R23,K$4:R$4)/SUM(K$4:R$4),2)) | T23: Da studiare | U23: TeamSystem ha fatto 7 acquisizioni nel comparto industria/costruzioni/real estate: segnale di valore del verticale. Mercato presidiato da gruppi grandi.
A24: 19 | B24: Scadenzario obblighi di sicurezza sul lavoro (formazione, visite, DPI) per PMI | C24: PMI manifatturiere e di servizi | D24: Acquisizioni di verticali | E24: Aventis Advisors (TeamSystem: legal, compliance, sicurezza) | I24: =IF(H24>0,ROUND(1000000/H24,0),"") | S24: =IF(COUNT(K24:R24)=0,"",ROUND(SUMPRODUCT(K24:R24,K$4:R$4)/SUM(K$4:R$4),2)) | T24: Da studiare | U24: 5 acquisizioni TeamSystem in legal/compliance/sicurezza. Prodotti già esistenti; da mappare i concorrenti.
A25: 20 | B25: Report di collaudo automatici da dati di misura per laboratori e officine | C25: Laboratori di prova, officine di precisione, assemblatori | D25: Altro | E25: idea precedente | F25: 3000 | G25: Accredia (31/12/2025): 1.448 laboratori di prova e 228 di taratura/altro; più laboratori interni non contati (affidabilità: Media) | H25: 1200 | I25: =IF(H25>0,ROUND(1000000/H25,0),"") | S25: =IF(COUNT(K25:R25)=0,"",ROUND(SUMPRODUCT(K25:R25,K$4:R$4)/SUM(K$4:R$4),2)) | T25: Da studiare | U25: Solo ipotesi nostra: domanda non verificata. Gli strumenti hanno già software di report. Vantaggio tuo: alto.
A26: 21 | B26: Scadenzario tarature degli strumenti di misura (ISO 9001) | C26: Officine, laboratori, PMI certificate | D26: Altro | E26: idea precedente | I26: =IF(H26>0,ROUND(1000000/H26,0),"") | S26: =IF(COUNT(K26:R26)=0,"",ROUND(SUMPRODUCT(K26:R26,K$4:R$4)/SUM(K$4:R$4),2)) | T26: Da studiare | U26: Solo ipotesi nostra: domanda non verificata.
A27: 22 | B27: Preventivatore con codici articolo per distributori tecnici | C27: Distributori di bulloneria, acciai, plastiche, macchine utensili | D27: Altro | E27: idea precedente | I27: =IF(H27>0,ROUND(1000000/H27,0),"") | S27: =IF(COUNT(K27:R27)=0,"",ROUND(SUMPRODUCT(K27:R27,K$4:R$4)/SUM(K$4:R$4),2)) | T27: Da studiare | U27: Solo ipotesi nostra: domanda non verificata. Probabile presenza di gestionali; da verificare.
A28: 23 | B28: Estrazione dati da ordini, DDT e preventivi in PDF per il back-office | C28: PMI con ufficio ordini | D28: Annunci di lavoro | E28: da cercare | I28: =IF(H28>0,ROUND(1000000/H28,0),"") | S28: =IF(COUNT(K28:R28)=0,"",ROUND(SUMPRODUCT(K28:R28,K$4:R$4)/SUM(K$4:R$4),2)) | T28: Da studiare | U28: Segnale da verificare: non cercato. Da cercare tra gli annunci per ruoli ripetitivi (ufficio ordini, data entry).
A29: 24 | B29: Assistente a documentazione tecnica per l'assistenza post-vendita dei costruttori di macchine | C29: Costruttori di macchine | D29: Altro | E29: idea Gemini | I29: =IF(H29>0,ROUND(1000000/H29,0),"") | S29: =IF(COUNT(K29:R29)=0,"",ROUND(SUMPRODUCT(K29:R29,K$4:R$4)/SUM(K$4:R$4),2)) | T29: Da studiare | U29: Solo ipotesi nostra: domanda non verificata.
A30: 25 | B30: Automazione di relazioni, perizie e pratiche per studi tecnici | C30: Studi di ingegneria e professionisti | D30: Altro | E30: studi contattati | I30: =IF(H30>0,ROUND(1000000/H30,0),"") | S30: =IF(COUNT(K30:R30)=0,"",ROUND(SUMPRODUCT(K30:R30,K$4:R$4)/SUM(K$4:R$4),2)) | T30: Da studiare | U30: Solo ipotesi nostra: domanda non verificata. Gli studi (DEAL, Parodi, Lommano) fanno pratiche antincendio, certificazioni energetiche, perizie.
A31: 26 | B31: Gestione dei file di misura RF e ottici per R&D e produzione | C31: Laboratori R&D e produzione elettronica | D31: Altro | E31: tuo campo | I31: =IF(H31>0,ROUND(1000000/H31,0),"") | S31: =IF(COUNT(K31:R31)=0,"",ROUND(SUMPRODUCT(K31:R31,K$4:R$4)/SUM(K$4:R$4),2)) | T31: Da studiare | U31: Solo ipotesi nostra: domanda non verificata. Vantaggio tuo: alto.
A32: 27 | B32: Schede di sicurezza e conformità CLP/REACH per chimica e gomma-plastica | C32: Aziende chimiche e della gomma-plastica | D32: Altro | E32: segmenti B2B (non verificati) | I32: =IF(H32>0,ROUND(1000000/H32,0),"") | S32: =IF(COUNT(K32:R32)=0,"",ROUND(SUMPRODUCT(K32:R32,K$4:R$4)/SUM(K$4:R$4),2)) | T32: Da studiare | U32: Segnale da verificare: non cercato.
A33: 28 | B33: Documentazione elettronica di lotto (batch record) per piccole aziende farmaceutiche/CDMO | C33: Piccole aziende farmaceutiche e CDMO | D33: Altro | E33: segmenti B2B (non verificati) | I33: =IF(H33>0,ROUND(1000000/H33,0),"") | S33: =IF(COUNT(K33:R33)=0,"",ROUND(SUMPRODUCT(K33:R33,K$4:R$4)/SUM(K$4:R$4),2)) | T33: Da studiare | U33: Segnale da verificare: non cercato. Barriera regolatoria alta (GMP).
A34: 29 | B34: Formazione e simulazioni di phishing per PMI (obblighi di formazione NIS2) | C34: PMI | D34: Obbligo di legge | E34: Noze; Agenda Digitale | I34: =IF(H34>0,ROUND(1000000/H34,0),"") | S34: =IF(COUNT(K34:R34)=0,"",ROUND(SUMPRODUCT(K34:R34,K$4:R$4)/SUM(K$4:R$4),2)) | T34: Da studiare | U34: Segnale verificato in ricerca (stampa di settore). Mercato affollato e a basso prezzo.
A35: 30 | B35: Manutenzione predittiva a basso costo per macchine di PMI manifatturiere | C35: PMI manifatturiere | D35: Altro | E35: idea nostra | I35: =IF(H35>0,ROUND(1000000/H35,0),"") | S35: =IF(COUNT(K35:R35)=0,"",ROUND(SUMPRODUCT(K35:R35,K$4:R$4)/SUM(K$4:R$4),2)) | T35: Da studiare | U35: Solo ipotesi nostra: domanda non verificata. Concorrenza forte (grandi fornitori).
A36: 31 | B36: Gestione documentale per sicurezza prodotti (GPSR) di importatori e venditori online | C36: Importatori e e-commerce di prodotti per consumatori | D36: Obbligo di legge | E36: da cercare | I36: =IF(H36>0,ROUND(1000000/H36,0),"") | S36: =IF(COUNT(K36:R36)=0,"",ROUND(SUMPRODUCT(K36:R36,K$4:R$4)/SUM(K$4:R$4),2)) | T36: Da studiare | U36: Segnale da verificare: non cercato.
A37: 32 | I37: =IF(H37>0,ROUND(1000000/H37,0),"") | S37: =IF(COUNT(K37:R37)=0,"",ROUND(SUMPRODUCT(K37:R37,K$4:R$4)/SUM(K$4:R$4),2))
A38: 33 | I38: =IF(H38>0,ROUND(1000000/H38,0),"") | S38: =IF(COUNT(K38:R38)=0,"",ROUND(SUMPRODUCT(K38:R38,K$4:R$4)/SUM(K$4:R$4),2))
A39: 34 | I39: =IF(H39>0,ROUND(1000000/H39,0),"") | S39: =IF(COUNT(K39:R39)=0,"",ROUND(SUMPRODUCT(K39:R39,K$4:R$4)/SUM(K$4:R$4),2))
A40: 35 | I40: =IF(H40>0,ROUND(1000000/H40,0),"") | S40: =IF(COUNT(K40:R40)=0,"",ROUND(SUMPRODUCT(K40:R40,K$4:R$4)/SUM(K$4:R$4),2))
A41: 36 | I41: =IF(H41>0,ROUND(1000000/H41,0),"") | S41: =IF(COUNT(K41:R41)=0,"",ROUND(SUMPRODUCT(K41:R41,K$4:R$4)/SUM(K$4:R$4),2))
...

Sheet Fase 2
A1: Fase 2 — dimensione dei mercati e quota necessaria per 1 M€ di ricavi (solo Italia)
A2: Numero di aziende: da fonti dove esistono, altrimenti ipotesi mie, con affidabilità indicata. I PREZZI SONO IPOTESI da validare nelle interviste. Le celle in blu si possono cambiare. 'Quota necessaria' = clienti per 1 M€ diviso aziende target: sopra circa il 10% il mercato italiano è troppo piccolo.
A4: Margine operativo ipotizzato | B4: 0.7
A5: Tassazione combinata (società + dividendi) | B5: 0.465
A6: Obiettivo netto mensile (€) | B6: 30000
A7: Netto mensile con 1 M€ di ricavi (€) | B7: =ROUND(1000000*B4*(1-B5)/12,0)
A8: Ricavi annui necessari per l'obiettivo (€) | B8: =ROUND(B6*12/(B4*(1-B5)),0)
A10: Nicchia | B10: Aziende target (bassa) | C10: Aziende target (base) | D10: Aziende target (alta) | E10: Fonte della stima | F10: Affidabilità | G10: Prezzo annuo (bassa) € | H10: Prezzo annuo (base) € | I10: Prezzo annuo (alta) € | J10: Clienti per 1 M€ (base) | K10: Quota necessaria (base) | L10: Quota (caso favorevole) | M10: Quota (caso sfavorevole) | N10: Lettura
A11: NIS2 per PMI | B11: 10000 | C11: 20000 | D11: 50000 | E11: Stampa di settore: 20.000–50.000 enti potenzialmente coinvolti (non registrati) | F11: Media | G11: 600 | H11: 1500 | I11: 4000 | J11: =ROUND(1000000/H11,0) | K11: =J11/C11 | L11: =(1000000/I11)/D11 | M11: =(1000000/G11)/B11 | N11: Base ampia, ma mercato affollato di consulenti: serve un canale forte.
A12: NIS2 per MSP e consulenti | B12: 2000 | C12: 5000 | D12: 10000 | E12: Mia ipotesi: numero di MSP e studi di consulenza IT rilevanti (nessun dato trovato) | F12: Bassa | G12: 1200 | H12: 2400 | I12: 6000 | J12: =ROUND(1000000/H12,0) | K12: =J12/C12 | L12: =(1000000/I12)/D12 | M12: =(1000000/G12)/B12 | N12: Vendi al canale: meno clienti ma con più aziende ciascuno. Da confrontare con le piattaforme esistenti.
A13: Cyber Resilience Act | B13: 1100 | C13: 3000 | D13: 8000 | E13: ANIE: ~1.100 aziende associate (altre fonti: 1.600); più costruttori con software. Perimetro CRA non trovato | F13: Bassa | G13: 1500 | H13: 3000 | I13: 6000 | J13: =ROUND(1000000/H13,0) | K13: =J13/C13 | L13: =(1000000/I13)/D13 | M13: =(1000000/G13)/B13 | N13: Norma europea: il mercato vero è più grande dell'Italia, ma va servito in inglese e con concorrenti internazionali.
A14: Direttiva RED (radio/IoT) | B14: 300 | C14: 800 | D14: 2000 | E14: Mia ipotesi: produttori e importatori di apparecchi radio in Italia (nessun dato trovato) | F14: Bassa | G14: 2000 | H14: 4000 | I14: 8000 | J14: =ROUND(1000000/H14,0) | K14: =J14/C14 | L14: =(1000000/I14)/D14 | M14: =(1000000/G14)/B14 | N14: Troppo piccolo come solo mercato italiano; ha senso solo come prodotto europeo.
A15: Regolamento Macchine | B15: 3000 | C15: 5000 | D15: 8000 | E15: Federmacchine 2020: 5.050 imprese (dato vecchio) | F15: Media-bassa | G15: 1500 | H15: 2500 | I15: 5000 | J15: =ROUND(1000000/H15,0) | K15: =J15/C15 | L15: =(1000000/I15)/D15 | M15: =(1000000/G15)/B15 | N15: Mercato ben definito e vicino a te; la scadenza (20/01/2027) può slittare.
A16: Iperammortamento 2026 (perizie) | B16: 5000 | C16: 12000 | D16: 20000 | E16: CNI 2020: 4,5%–9% degli ingegneri ha firmato perizie, in media 10 ciascuno (+ ordine di grandezza mio) | F16: Bassa | G16: 300 | H16: 600 | I16: 1500 | J16: =ROUND(1000000/H16,0) | K16: =J16/C16 | L16: =(1000000/I16)/D16 | M16: =(1000000/G16)/B16 | N16: Tanti utenti ma prezzo basso: serve come aggiunta a un prodotto più grande.
A17: Fibra ottica (posa) | B17: 300 | C17: 1000 | D17: 3000 | E17: Mia ipotesi: nessun dato trovato sul numero di imprese di posa | F17: Bassa | G17: 1000 | H17: 2000 | I17: 4000 | J17: =ROUND(1000000/H17,0) | K17: =J17/C17 | L17: =(1000000/I17)/D17 | M17: =(1000000/G17)/B17 | N17: Mercato piccolo e dipendente da pochi committenti.
A18: FWA (piccoli operatori) | B18: 200 | C18: 400 | D18: 1000 | E18: Consulente 2022: 'centinaia' di WISP in Italia | F18: Bassa | G18: 800 | H18: 1500 | I18: 3000 | J18: =ROUND(1000000/H18,0) | K18: =J18/C18 | L18: =(1000000/I18)/D18 | M18: =(1000000/G18)/B18 | N18: Troppo piccolo come mercato solo italiano.
A19: Report di collaudo | B19: 1700 | C19: 3000 | D19: 10000 | E19: Accredia (31/12/2025): 1.448 laboratori di prova e 228 di taratura/altro; più laboratori interni non contati | F19: Media | G19: 600 | H19: 1200 | I19: 3000 | J19: =ROUND(1000000/H19,0) | K19: =J19/C19 | L19: =(1000000/I19)/D19 | M19: =(1000000/G19)/B19 | N19: Mercato di nicchia; gli strumenti di misura hanno già report inclusi.
A21: Come leggerla
A22: Le norme europee (CRA, RED, Macchine) si applicano in tutta l'UE: il mercato reale può essere molte volte quello italiano, ma richiede un prodotto in inglese e concorrenti internazionali.
A23: Per numeri precisi sulle aziende per codice ATECO e classe di addetti servono le tavole Istat (ASIA) su IstatData: scaricale e le analizzo. Dal mio ambiente non sono raggiungibili.
A24: Nessun numero di questo foglio è un dato di mercato verificato per il tuo prodotto: sono ordini di grandezza per scartare le nicchie troppo piccole.

Sheet Segmenti B2B
A1: Segmenti B2B lombardi con ricavi sopra 1 M€ — DATI NON VERIFICATI
A2: Stime fornite da un altro chatbot, senza fonte. Servono come ipotesi di lavoro per scegliere dove guardare. Da confermare con i dati Istat (unità locali per ATECO e classe di addetti) e della Camera di Commercio prima di usarle in qualsiasi decisione.
A4: Segmento | B4: Quota stimata | C4: Aziende (stima) | D4: Verificato? | E4: Fonte verificata
A5: Manifattura avanzata e meccanica | B5: 26–28% | C5: 11.000–11.500 | D5: No
A6: Commercio all'ingrosso B2B | B6: 20–22% | C6: 8.500–9.000 | D6: No
A7: Servizi corporate, ICT e software | B7: 12–14% | C7: 5.000–5.800 | D7: No
A8: Costruzioni, impiantistica, real estate B2B | B8: 10–12% | C8: 4.200–4.800 | D8: No
A9: Chimica, polimeri, gomma-plastica | B9: 7–8% | C9: 3.000–3.300 | D9: No
A10: Logistica, spedizioni e trasporti B2B | B10: 6–7% | C10: 2.500–2.900 | D10: No
A11: Farmaceutica, biotech, dispositivi medici | B11: 4–5% | C11: 1.600–2.000 | D11: No
A12: Energia, ambiente, utilities B2B | B12: 3–4% | C12: 1.300–1.600 | D12: No
A13: Telecomunicazioni e reti | B13: 1,5–2% | C13: 600–800 | D13: No
A15: Altre cifre da verificare
A16: Quota di aziende lombarde con ricavi >1 M€ per forma giuridica: ditte individuali <0,5%, società di persone ~17%, società di capitali ~34% (fornite da te, senza fonte).
A17: B2B contro B2C: ~11-12% delle imprese B2B sopra 1 M€ contro ~2% delle B2C (altro chatbot, senza fonte). La direzione è plausibile, il rapporto 5-6x no.
A18: Ripartizione B2B/B2C per forma giuridica: individuali 65/35, persone 55/45, capitali 60/40 (tue stime).

Sheet Fonti
A1: Fonti dei segnali (consultate fino al 30/10/2026)
A2: Quasi tutte sono stampa di settore e blog di consulenza, non testi ufficiali: le date vanno confermate sulla fonte primaria.
A4: NIS2 | B4: https://www.noze.it/insights/nis2-pmi-cyberagent/
B5: https://www.agendadigitale.eu/sicurezza/nis2-scadenze-2026-la-guida-per-le-piccole-imprese/
A7: AI Act | B7: https://www.agendadigitale.eu/industry-4-0/digital-omnibus-e-ai-act-cosa-puo-slittare-e-cosa-va-fatto-prima-di-agosto-2026/
B8: https://www.noze.it/insights/ai-act-digital-omnibus-2026/
A10: Cyber Resilience Act | B10: https://www.agendadigitale.eu/sicurezza/cyber-resilience-act-la-scadenza-chiave-arriva-l11-settembre-2026/
B11: https://www.ipsoa.it/documents/quotidiano/2026/09/02/cyber-resilience-act-11-settembre-2026-scatta-obbligo-segnalare-vulnerabilita-incidenti-gravi
A13: Direttiva RED | B13: https://www.tuvsud.com/en-us/services/product-certification/red-cybersecurity-requirements
B14: https://www.yarix.com/Advisory-and-Consulting-Services/RED-Compliance
A16: Regolamento Macchine | B16: https://certifico.com/macchine/regolamento-ue-2023-1230
B17: https://www.ilsussidiario.net/news/regolamento-macchine-ue-rosa-ucimu-mancano-criteri-comuni-e-chiari-serve-una-proroga/2986256/amp/
A19: Trasparenza retributiva | B19: https://quifinanza.it/lavoro/trasparenza-salariale-7-giugno-2026/960990/
B20: https://www.partitaiva.it/trasparenza-salariale/
A22: PPWR | B22: https://www.assolombarda.it/servizi/ambiente/informazioni/ppwr-dal-12-agosto-in-applicazione-il-nuovo-regolamento-ue-sugli-imballaggi
A24: Passaporto digitale di prodotto | B24: https://www.bluestonepim.com/blog/digital-product-passport-for-batteries
B25: https://www.pmi.it/tecnologia/prodotti-e-servizi-ict/492107/passaporto-digitale-prodotto.html
A27: Accessibilità (EAA) | B27: https://www.agendadigitale.eu/mercati-digitali/ecommerce/siti-ecommerce-accessibili-guida-in-5-step-per-evitare-sanzioni/
B28: https://www.iubenda.com/it/help/178476-accessibilita-101/
A30: Iperammortamento 2026 | B30: https://www.agendadigitale.eu/industry-4-0/iperammortamento-2026-la-guida-cose-e-come-fare-le-comunicazioni-al-gse/
B31: https://pasqualepillitteri.it/perizia-iperammortamento
A33: Acquisizioni TeamSystem / Zucchetti | B33: https://aventis-advisors.com/teamsystem-acquisitions/
A35: Piano Italia 1 Giga | B35: https://www.editorialedomani.it/economia/banda-ultralarga-cantieri-obiettivi-pnrr-ritardi-regioni-oqbs3i02
B36: https://tariffe.segugio.it/news-tariffe/italia-1-giga-nuovi-ritardi-per-la-banda-ultra-larga-cosa-sta-succedendo-00043657.aspx
A38: FWA e frequenze 26 GHz | B38: https://tariffe.segugio.it/news-tariffe/internet-senza-fibra-la-fwa-supera-2-7-milioni-di-linee-00047779.aspx
B39: https://www.smartworld.it/news/frequenze-5g-26-ghz-gara-italia-agosto-2026.html
A41: Fase 2 — numeri di mercato | B41: https://accredia.it/wp-content/uploads/2024/07/Cartella-stampa-breve-dati-al-31-12-2025_ITA-1.pdf
B42: https://assomac.it/media/documents/rapporto_federmacchine_2020.pdf
B43: https://anie.it/federazione/chi-siamo/rapporto-annuale-2025_def
B44: https://www.cni.it/images/eventi/2021/01_Lelaborazione_delle_perizie_13lug2021.pdf
B45: https://www.fibertelecom.com/wt/2022/PDF/02-puglia/FTWWT2022-puglia-03.pdf
A47: Comunità energetiche (CER) | B47: https://www.infobuildenergia.it/approfondimenti/cer-comunita-energetiche-in-italia/
